Workbook

Sheet 2024
A1: School Type | B1: School No | C1: School Name | D1: ACAD | E1: Dropped/Retained | F1: Academic Year | G1: SSF Date | H1: Offering | I1: School Revenue Type | J1: SSF Number | K1: Status | L1: Total Order Value (Exclusive GST) | M1: Total Order Value (Inclusive GST) | N1: ASSET Revenue | O1: ASSETStudents | P1: ASSET rate | Q1: CARES Revenue | R1: CARESStudents | S1: CARES rate | T1: Mindspark Revenue | U1: MindsparkStudents | V1: Mindspark rate | W1: Teacher Training Revenue | X1: Payment Mode | Y1: No Of Installments | Z1: Full Payment Date | AA1: First Installment Date | AB1: First Installment Amount | AC1: Second Installment Date | AD1: Second Installment Amount | AE1: Third Installment Date | AF1: Third Installment Amount | AG1: Fourth Installment Date | AH1: Fourth Installment Amount | AI1: TDS Amount | AJ1: First payment Date | AK1: Latest payment Date | AL1: To be invoiced till date | AM1: Amount Received | AN1: Due till date as per payment schedule | AO1: Total Discount % | AP1: Standard Discount % | AQ1: Pre Payment Discount % | AR1: Volume Discount % | AS1: Bundle Discount % | AT1: Loyalty Discount % | AU1: ASSETRound | AV1: Ei ASSET Mode | AW1: CAREStestpack | AX1: Ei CARES Version | AY1: Ei CARES Mode Of Printing | AZ1: Ei CARES Mode | BA1: Ei Mindspark Mode | BB1: Board | BC1: City | BD1: State | BE1: Division | BF1: Zone | BG1: Vertical | BH1: Program Start Date | BI1: Program End Date | BJ1: Order Type | BK1: ID | BL1: Zoho CRM Account ID | BM1: Deal ID | BN1: Created Date | BO1: Added User | BP1: Modified User | BQ1: SSF Creator Email | BR1: SSF Creator | BS1: CRM Account Owner | BT1: CRM Acad Consultant | BU1: Logistic Approved Date | BV1: SSF Signing Perosn Name | BW1: SSF Signing Perosn Designation | BX1: SSF Signing Perosn Mail ID | BY1: SSF Signing Perosn Phone No | BZ1: School CRM Email | CA1: Principal Name | CB1: Principal Email | CC1: Principal Phone No | CD1: Coordinator Name | CE1: Coordinator Email | CF1: Coordinator Phone No | CG1: School Fees | CH1: Billing Address Line 1 | CI1: Billing Address Line 2 | CJ1: Billing Postal Code | CK1: Shipping Address Line 1 | CL1: Shipping City | CM1: Shipping State | CN1: Shipping Postal Code | CO1: TAN NO | CP1: CRM Billing Street | CQ1: CRM Shipping Street
A2: 1-year School | B2: 1002463 | C2: Cambridge School, New Friends Colony | D2: =VLOOKUP(B2,'2025'!B:C,2,0) -> Vaishali | F2: 2024 | G2: 2024-04-30 00:00:00 | H2: Ei ASSET | I2: Regular | J2: IN-2022001979 | K2: Approved By Logistic Team | L2: 267000 | M2: 267000 | N2: 267000 | O2: 356 | P2: 750 | Q2: 0 | R2: 0 | T2: 0 | U2: 0 | W2: 0 | X2: Installments | Y2: 2 | AA2: 2024-05-07 00:00:00 | AB2: 80100 | AC2: 2024-11-07 00:00:00 | AD2: 186900 | AE2: 2000-01-01 00:00:00 | AF2: 0 | AG2: 2000-01-01 00:00:00 | AH2: 0 | AI2: 5340 | AJ2: 2024-06-28 00:00:00 | AK2: 2025-01-21 00:00:00 | AL2: 267000 | AM2: 261659 | AN2: 1 | AO2: 0.5 | AP2: 0.5 | AU2: Winter Round | AV2: OMR | AW2: 0 | AX2: MCQ | BB2: CBSE | BC2: Delhi | BD2: Delhi | BE2: North | BF2: Delhi/Haryana | BG2: National Sales | BH2: 2024-05-01 00:00:00 | BI2: 2025-03-31 00:00:00 | BJ2: Regular School: Active school with student count and rate per student defined | BK2: 22028000022319092 | BL2: 51788000002746818 | BM2: zcrm_51788000269056279 | BN2: 2024-04-30 00:00:00 | BO2: puneet.khurana_ei | BP2: hakim.kanchwala_eiindia1 | BQ2: puneet.khurana@ei.study | BR2: Puneet khurana | BS2: Vaishali Yadav | BU2: 2024-05-13 09:06:54 | BV2: Mrs. Sunandita Ganguly | BW2: Principal | BX2: sunandita.nfc@cambridgeschool.edu.in | BY2: +919711953984 | BZ2: mailus.nfc@cambridgeschool.edu.in | CA2: Mrs. Sunandita Ganguly | CB2: sunandita.nfc@cambridgeschool.edu.in | CC2: +919711953984 | CD2: Ms Latika Mehra | CE2: latikam.nfc@cambridgeschool.edu.in | CF2: +919810606517 | CG2: 88500 | CH2: A - Block, A 96 New Friends Colony, ,Delhi,Delhi - 110065 | CJ2: 110065 | CK2: A - Block, A 96 New Friends Colony, ,Delhi,Delhi - 110065 | CL2: Delhi | CM2: Delhi | CN2: 110065 | CO2: PNEK06448B | CP2: A - Block, A 96 New Friends Colony, ,Delhi,Delhi - 110065 | CQ2: A - Block, A 96 New Friends Colony, ,Delhi,Delhi - 110065
A3: Retention School | B3: 1016619 | C3: St. Paul'S School | D3: =VLOOKUP(B3,'2025'!B:C,2,0) -> Lopamudra Das | F3: 2024 | G3: 2024-06-25 00:00:00 | H3: Ei CARES | I3: Regular | J3: IN-2022002275 | K3: Approved By Logistic Team | L3: 1014560 | M3: 1014560 | N3: 0 | O3: 0 | Q3: 1014560 | R3: 1166 | S3: 870 | T3: 0 | U3: 0 | W3: 0 | X3: Installments | Y3: 4 | AA3: 2024-06-29 00:00:00 | AB3: 253640 | AC3: 2024-08-31 00:00:00 | AD3: 253640 | AE3: 2024-10-31 00:00:00 | AF3: 253640 | AG3: 2024-12-31 00:00:00 | AH3: 253640 | AI3: 101631 | AJ3: 2024-07-22 00:00:00 | AK3: 2025-01-20 00:00:00 | AL3: 1014560 | AM3: 914669 | AN3: -1740 | AO3: 0.5166 | AP3: 0.46659999999999996 | AT3: 0.05 | AU3: 0 | AW3: 2 | AX3: MCQ | AY3: Printing By EI | AZ3: OMR | BB3: CISCE | BC3: Rourkela | BD3: Odisha | BE3: East | BF3: Odisha | BG3: National Sales | BH3: 2024-06-24 00:00:00 | BI3: 2025-03-31 00:00:00 | BJ3: Regular School: Active school with student count and rate per student defined | BK3: 22028000023176128 | BL3: 51788000002747044 | BM3: zcrm_51788000270481001 | BN3: 2024-06-25 00:00:00 | BO3: lopamudra.das_eiindia1 | BP3: mitul.patel_ei1 | BQ3: lopamudra.das@ei.study | BR3: Lopamudra das | BS3: Lopamudra Das | BU3: 2024-07-01 10:19:15 | BV3: Fr. Joseph Sarpira Sadam | BW3: Principal | BX3: stpaulrkl@gmail.com | BY3: +919437290604 | BZ3: stpaulrkl@gmail.com | CG3: 0 | CH3: Hamirpur, Rourkela - 769003, Odisha, INDIA. | CJ3: 769003 | CK3: Hamirpur, Rourkela - 769003, Odisha, INDIA. | CL3: Rourkela | CM3: Odisha | CN3: 769003 | CO3: BBNT00367D | CP3: Hamirpur, Rourkela - 769003, Odisha, INDIA. | CQ3: Hamirpur, Rourkela - 769003, Odisha, INDIA.
A4: Retention School | B4: 1019428 | C4: KLE KG & English Medium State School, Nipani | F4: 2024 | G4: 2024-06-16 00:00:00 | H4: Ei ASSET, Ei Mindspark | I4: Regular | J4: IN-2022002210, IN-2022002237 | K4: Approved By Logistic Team | L4: 674546 | M4: 750348 | N4: 253424 | O4: 815 | P4: 311 | Q4: 0 | R4: 0 | T4: 421122 | U4: 828 | V4: 509 | W4: 0 | X4: Installments | Y4: 2 | AA4: 2024-07-15 00:00:00 | AB4: 126712, 248462 | AC4: 2024-11-15 00:00:00, 2024-12-15 00:00:00 | AD4: 126712, 248462 | AE4: 2000-01-01 00:00:00 | AF4: 0 | AG4: 2000-01-01 00:00:00 | AH4: 0 | AI4: 25408.7, 41542 | AJ4: 2024-09-05 00:00:00, 2024-09-18 00:00:00 | AK4: 2025-01-17 00:00:00 | AL4: 253424, 496924 | AM4: 228678.3, 448658 | AN4: -663, 6724 | AO4: 0.7927, 0.8332999999999999 | AP4: 0.7927, 0.8332999999999999 | AU4: 0, Winter Round | AV4: OMR | AW4: 0 | AX4: MCQ | BA4: Offline | BB4: State Board | BC4: Nipani | BD4: Karnataka | BE4: South | BF4: Karnataka/Kerala | BG4: National Sales | BH4: 2024-06-01 00:00:00 | BI4: 2025-04-30 00:00:00, 2025-05-31 00:00:00 | BJ4: Regular School: Active school with student count and rate per student defined | BK4: 22028000023002408, 22028000023033488 | BL4: 51788000002747167 | BM4: zcrm_51788000270604012, zcrm_51788000270690656 | BN4: 2024-06-16 00:00:00 | BO4: vineet.upadhye_ei | BP4: mitul.patel_ei1 | BQ4: vineet.upadhye@ei.study | BR4: Vineet upadhye | BS4: Nisha Murali | BU4: 2024-06-18 10:41:02, 2024-06-18 10:43:54 | BV4: Maruf Shaikh | BX4: maruf.shaikh@ei.study | BY4: +919016039311 | BZ4: kleems@rediffmail.com | CG4: 0 | CH4: Old P.B road Nipani | CJ4: 591237 | CK4: Old P.B road Nipani | CL4: Nipani | CM4: Karnataka | CN4: 591237 | CO4: BLRK04875D | CP4: Old P.B road Nipani | CQ4: Old P.B road Nipani
A5: Retention School | B5: 1021816 | C5: The Doon Girls^ School | D5: =VLOOKUP(B5,'2025'!B:C,2,0) -> Tanya | F5: 2024 | G5: 2024-04-01 00:00:00 | H5: Ei ASSET,Ei CARES, Ei Mindspark | I5: Regular | J5: IN-2022001799, IN-2022001800 | K5: Approved By Logistic Team | L5: 344761 | M5: 371278 | N5: 46902 | O5: 79 | P5: 594 | Q5: 150542 | R5: 79 | S5: 1906 | T5: 147317 | U5: 79 | V5: 1865 | W5: 0 | X5: Installments | Y5: 4 | AA5: 2024-04-15 00:00:00 | AB5: 43459, 49361 | AC5: 2024-07-15 00:00:00 | AD5: 43459, 49361 | AE5: 2024-10-15 00:00:00 | AF5: 43459, 49361 | AG5: 2024-12-31 00:00:00 | AH5: 43459, 49361 | AI5: 0 | AJ5: 2024-09-13 00:00:00 | AK5: 2024-09-13 00:00:00, 2024-12-26 00:00:00 | AL5: 173836, 197444 | AM5: 236917, 87395 | AN5: -63081, 110049 | AO5: 0.6944, 0.7618 | AP5: 0.6944, 0.7618 | AU5: 0, Summer Round | AV5: OMR | AW5: 0, 8 | AX5: MCQ, MCQ + Subjective | AZ5: Online | BA5: Online | BB5: CISCE | BC5: Dehradun | BD5: Uttarakhand | BE5: North | BF5: UP/Uttarakhand | BG5: National Sales | BH5: 2024-04-01 00:00:00 | BI5: 2025-03-31 00:00:00 | BJ5: Regular School: Active school with student count and rate per student defined | BK5: 22028000021869840, 22028000021869888 | BL5: 51788000002747187 | BM5: zcrm_51788000267771001, zcrm_51788000267801001 | BN5: 2024-04-01 00:00:00 | BO5: anshul.nagpal_ei | BP5: sourabh.mehta_eiindia | BQ5: anshul.nagpal@ei.study | BR5: Anshul nagpal | BS5: Tanya Marina Brooks | BU5: 2024-04-04 17:12:47, 2024-04-04 17:12:52 | BV5: Ms. Monisha Dutta | BW5: Principal | BX5: doongirlsschool@gmail.com | BY5: +919927683344 | BZ5: doongirlsschool@gmail.com | CA5: Ms. Monisha Dutta | CB5: doongirlsschool@gmail.com | CC5: +919927683344 | CD5: Mr. Rohit Raj Singh | CE5: rrs@thedoongirlsschool.com | CF5: +919634483993 | CG5: 0 | CH5: 4, Circular Road, Dalanwala, | CJ5: 248001 | CK5: 4, Circular Road, Dalanwala, | CL5: Dehradun | CM5: Uttarakhand | CN5: 248001 | CP5: 4, Circular Road, Dalanwala, | CQ5: 4, Circular Road, Dalanwala,
A6: Retention School | B6: 10251 | C6: Sri Aurobindo International School | F6: 2024 | G6: 2024-04-04 00:00:00, 2024-08-09 00:00:00 | H6: Ei CARES | I6: Regular | J6: IN-2022001852, IN-2022001853, IN-2022002413 | K6: Approved By Logistic Team | L6: 904469 | M6: 904469 | N6: 0 | O6: 0 | Q6: 904469 | R6: 729 | S6: 0, 1202, 2090 | T6: 0 | U6: 0 | W6: 0 | X6: Full Payment | Z6: 2024-03-31 00:00:00, 2024-04-30 00:00:00 | AA6: 2000-01-01 00:00:00 | AB6: 0 | AC6: 2000-01-01 00:00:00 | AD6: 0 | AE6: 2000-01-01 00:00:00 | AF6: 0 | AG6: 2000-01-01 00:00:00 | AH6: 0 | AI6: 0, 4206, 84866 | AJ6: 2024-05-07 00:00:00 | AK6: 2024-05-07 00:00:00 | AL6: 0, 43264, 861205 | AM6: 0, 37856, 763797 | AN6: 0, 1202, 12542 | AO6: 0.5229, 0.5916, 1 | AP6: 0.4729, 0.5416, 1 | AQ6: 0.05 | AU6: 0 | AW6: 2, 6, 8 | AX6: MCQ | AZ6: Online | BB6: CISCE | BC6: Hyderabad | BD6: Telangana | BE6: South | BF6: AP/Telangana | BG6: National Sales | BH6: 2024-06-01 00:00:00 | BI6: 2025-03-31 00:00:00 | BJ6: Regular School: Active school with student count and rate per student defined | BK6: 22028000021919812, 22028000021919844, 22028000024041572 | BL6: 51788000002728476 | BM6: zcrm_51788000267805111, zcrm_51788000267805248, zcrm_51788000272301001 | BN6: 2024-04-04 00:00:00, 2024-08-09 00:00:00 | BO6: chaitanya.kolluri_ei | BP6: hakim.kanchwala_eiindia1 | BQ6: chaitanya.kolluri@ei.study | BR6: Chaitanya kolluri | BS6: Jasper Jessie | BU6: 2024-04-22 14:51:39, 2024-04-22 14:51:44, 2024-08-10 12:50:42 | BV6: Mr. Praveen, Mr. Praveen SAIS | BW6: Accounts | BX6: saishyd@gmail.com | BY6: +919849659075 | CA6: Ms. Vinjamur Jayashree | CB6: vinjamurjayashree@gmail.com | CD6: Ms. Meena Murthy | CE6: gmlochani@gmail.com | CF6: +919866561332 | CG6: 0 | CH6: 2-2-4/1 O U Road, Sri Aurobindo Marg,Vidyanagar, | CJ6: 500044 | CK6: 2-2-4/1 O U Road, Sri Aurobindo Marg,Vidyanagar, | CL6: Hyderabad | CM6: Telangana | CN6: 500044 | CO6: HYDI01894E | CP6: Vidyanagar, | CQ6: Vidyanagar,
A7: 1-year School | B7: 1026343 | C7: Mind Tree School, Ambala City | D7: =VLOOKUP(B7,'2025'!B:C,2,0) -> Bhavishya | F7: 2024 | G7: 2024-06-28 00:00:00 | H7: Ei ASSET | I7: Regular | J7: IN-2022002289 | K7: Approved By Logistic Team | L7: 96600 | M7: 96600 | N7: 96600 | O7: 161 | P7: 600 | Q7: 0 | R7: 0 | T7: 0 | U7: 0 | W7: 0 | X7: Full Payment | Z7: 2024-08-05 00:00:00 | AA7: 2000-01-01 00:00:00 | AB7: 0 | AC7: 2000-01-01 00:00:00 | AD7: 0 | AE7: 2000-01-01 00:00:00 | AF7: 0 | AG7: 2000-01-01 00:00:00 | AH7: 0 | AI7: 5880 | AJ7: 2024-08-27 00:00:00 | AK7: 2024-08-27 00:00:00 | AL7: 96600 | AM7: 52920 | AN7: 37800 | AO7: 0.6 | AP7: 0.6 | AU7: Summer Round | AV7: OMR | AW7: 0 | AX7: MCQ | BB7: CBSE | BC7: Ambala | BD7: Haryana | BE7: North | BF7: Delhi/Haryana | BG7: National Sales | BH7: 2024-05-13 00:00:00 | BI7: 2025-03-31 00:00:00 | BJ7: Regular School: Active school with student count and rate per student defined | BK7: 22028000023208508 | BL7: 51788000002747228 | BM7: zcrm_51788000255130095 | BN7: 2024-06-28 00:00:00 | BO7: gaurav.mehta_eiindia | BP7: sourabh.mehta_eiindia | BQ7: gaurav.mehta@ei.study | BR7: Gaurav mehta | BS7: Bhavishya Bansal | BU7: 2024-07-01 13:00:38 | BV7: Ms. Neelam Ohri | BW7: Principal | BX7: mindtree.ambala@gmail.com | BY7: +918685000121 | BZ7: mindtreeschool@gmail.com | CG7: 48000 | CH7: Mind Tree School, Sector 1 | CJ7: 134011 | CK7: Mind Tree School, Sector 1 | CL7: Ambala | CM7: Haryana | CN7: 134011 | CP7: Mind Tree School, Sector 1 | CQ7: Mind Tree School, Sector 1
A8: Retention School | B8: 10423 | C8: Shri Shikshayatan School | D8: =VLOOKUP(B8,'2025'!B:C,2,0) -> Lopa | F8: 2024 | G8: 2024-03-08 00:00:00 | H8: Ei ASSET | I8: Regular | J8: IN-2022001599 | K8: Approved By Logistic Team | L8: 649545 | M8: 649545 | N8: 649545 | O8: 1300 | P8: 500 | Q8: 0 | R8: 0 | T8: 0 | U8: 0 | W8: 0 | X8: Installments | Y8: 2 | AA8: 2024-04-22 00:00:00 | AB8: 194864 | AC8: 2024-07-04 00:00:00 | AD8: 454682 | AE8: 2000-01-01 00:00:00 | AF8: 0 | AG8: 2000-01-01 00:00:00 | AH8: 0 | AI8: 9486 | AJ8: 2024-06-25 00:00:00 | AK8: 2025-02-13 00:00:00 | AL8: 649546 | AM8: 620955 | AN8: 19105 | AO8: 0.6668999999999999 | AP8: 0.6668999999999999 | AU8: Summer Round | AV8: OMR | AW8: 0 | AX8: MCQ | BB8: CBSE | BC8: Kolkata | BD8: West Bengal | BE8: East | BF8: West Bengal | BG8: National Sales | BH8: 2024-04-08 00:00:00 | BI8: 2025-03-31 00:00:00 | BJ8: Regular School: Active school with student count and rate per student defined | BK8: 22028000021440040 | BL8: 51788000002728478 | BM8: zcrm_51788000266368106 | BN8: 2024-03-08 00:00:00 | BO8: ratnabali.mukherjee_eiindia | BP8: mitul.patel_ei1 | BQ8: ratnabali.mukherjee@ei.study | BR8: Ratnabali mukherjee | BS8: Gargi Ghosh | BU8: 2024-04-24 14:37:25 | BV8: Mrs. Sangeeta Tandon | BW8: Principal | BX8: principal@shrishikshayatanschool.com | BY8: +919831872819 | BZ8: principal@shrishikshayatanschool.com | CA8: Mrs. Sangeeta Tandon | CB8: principal@shrishikshayatanschool.com | CC8: +919831872819 | CD8: Rupali | CE8: principal@shrishikshayatanschool.com | CF8: +918100376881 | CG8: 0 | CH8: 11, Lord Sinha Road, Elgin, | CJ8: 700071 | CK8: 11, Lord Sinha Road, Elgin, | CL8: Kolkata | CM8: West Bengal | CN8: 700071 | CO8: CALS05598F | CP8: 11, Lord Sinha Road, Elgin, | CQ8: 11, Lord Sinha Road, Elgin,
A9: Retention School | B9: 104830 | C9: P.S. Senior Secondary School | D9: =VLOOKUP(B9,'2025'!B:C,2,0) -> Vineeth T V | F9: 2024 | G9: 2024-01-24 00:00:00 | H9: Ei CARES | I9: Regular | J9: IN-2022001422 | K9: Approved By Logistic Team | L9: 1609105 | M9: 1609105 | N9: 0 | O9: 0 | Q9: 1609105 | R9: 1192 | S9: 1350 | T9: 0 | U9: 0 | W9: 0 | X9: Installments | Y9: 3 | AA9: 2024-06-01 00:00:00 | AB9: 482732 | AC9: 2024-08-01 00:00:00 | AD9: 563187 | AE9: 2024-12-01 00:00:00 | AF9: 563187 | AG9: 2000-01-01 00:00:00 | AH9: 0 | AI9: 157940 | AJ9: 2024-06-24 00:00:00 | AK9: 2024-12-17 00:00:00 | AL9: 1609106 | AM9: 1421466 | AN9: 29700 | AO9: 0.4808 | AP9: 0.4808 | AU9: 0 | AW9: 4 | AX9: MCQ | AY9: Printing By EI | AZ9: OMR | BB9: CBSE | BC9: Chennai | BD9: Tamil Nadu | BE9: South | BF9: Tamil Nadu | BG9: National Sales | BH9: 2024-06-01 00:00:00 | BI9: 2025-04-30 00:00:00 | BJ9: Regular School: Active school with student count and rate per student defined | BK9: 22028000020766924 | BL9: 51788000002731864 | BM9: zcrm_51788000263929001 | BN9: 2024-01-24 00:00:00 | BO9: nisha.murali_eiindia | BP9: hakim.kanchwala_eiindia1 | BQ9: nisha.murali@ei.study | BR9: Nisha murali | BS9: Vineeth T V | BU9: 2024-02-01 14:54:01 | BV9: Mrs.Revathy Parameswaran | BW9: Principal | BX9: Pssrsec@gmail.com | BY9: +919444907456 | BZ9: pssrsec@gmail.com | CA9: Mrs.Revathy Parameswaran | CB9: Pssrsec@gmail.com | CC9: +919444907456 | CD9: Shivakumar | CE9: prsivaku042@gmail.com | CF9: +919677100124 | CG9: 0 | CH9: 33 Alarmelmangapuram, Mylapore, Chennai Â 600 004 | CJ9: 600004 | CK9: 33 Alarmelmangapuram, Mylapore, Chennai Â 600 004 | CL9: Chennai | CM9: Tamil Nadu | CN9: 600004 | CO9: CHEP02342E | CP9: 33 Alarmelmangapuram, Mylapore, Chennai Â 600 004 | CQ9: 33 Alarmelmangapuram, Mylapore, Chennai Â 600 004
A10: New School | B10: 1061266 | C10: Ingraham Institute English School | E10: Dropped | F10: 2024 | G10: 2024-05-14 00:00:00 | H10: Ei CARES | I10: Regular | J10: IN-2022002053 | K10: Approved By Logistic Team | L10: 583833 | M10: 583833 | N10: 0 | O10: 0 | Q10: 583833 | R10: 556 | S10: 1050 | T10: 0 | U10: 0 | W10: 0 | X10: Installments | Y10: 4 | AA10: 2024-05-18 00:00:00 | AB10: 58383 | AC10: 2024-08-01 00:00:00 | AD10: 233533 | AE10: 2024-10-01 00:00:00 | AF10: 145958 | AG10: 2024-12-02 00:00:00 | AH10: 145958 | AI10: 61348 | AJ10: 2024-06-21 00:00:00 | AK10: 2025-03-12 00:00:00 | AL10: 583832 | AM10: 552148 | AN10: -29664 | AO10: 0.5227 | AP10: 0.5227 | AU10: 0 | AW10: 2 | AX10: MCQ + Subjective | AY10: Printing By EI | AZ10: OMR | BB10: CISCE | BC10: Ghaziabad | BD10: Uttar Pradesh | BE10: North | BF10: NCR | BG10: National Sales | BH10: 2024-05-20 00:00:00 | BI10: 2025-03-31 00:00:00 | BJ10: Regular School: Active school with student count and rate per student defined | BK10: 22028000022495488 | BL10: 51788000002747830 | BM10: zcrm_51788000261218012 | BN10: 2024-05-14 00:00:00 | BO10: puneet.khurana_ei | BP10: sourabh.mehta_eiindia | BQ10: puneet.khurana@ei.study | BR10: Puneet khurana | BS10: Puneet Khurana | BT10: Vaishali Yadav | BU10: 2024-05-16 14:47:22 | BV10: Mrs. Arpana Ruth | BW10: Principal | BX10: arpana2@yahoo.com | BY10: +919971995516 | BZ10: ingrinst@gmail.com | CA10: Mrs. Arpana Ruth | CB10: arpana2@yahoo.com | CC10: +919971995516 | CG10: 0 | CH10: Hapur Road | CJ10: 201001 | CK10: Hapur Road | CL10: Ghaziabad | CM10: Uttar Pradesh | CN10: 201001 | CP10: Hapur Road | CQ10: Hapur Road
A11: 1-year School | B11: 108345 | C11: Manasarowar Pushkarini Vidyashrama | E11: Dropped | F11: 2024 | G11: 2024-03-27 00:00:00 | H11: Ei ASSET | I11: Regular | J11: IN-2022001755 | K11: Approved By Logistic Team | L11: 1282717 | M11: 1282717 | N11: 1282717 | O11: 1166 | P11: 1100 | Q11: 0 | R11: 0 | T11: 0 | U11: 0 | W11: 0 | X11: Installments | Y11: 2 | AA11: 2024-06-14 00:00:00 | AB11: 641359 | AC11: 2024-08-14 00:00:00 | AD11: 641359 | AE11: 2000-01-01 00:00:00 | AF11: 0 | AG11: 2000-01-01 00:00:00 | AH11: 0 | AI11: 68037 | AJ11: 2024-08-01 00:00:00 | AK11: 2024-12-23 00:00:00 | AL11: 1282718 | AM11: 1196976 | AN11: 17705 | AO11: 0.2666 | AP11: 0.2666 | AU11: Summer Round | AV11: OMR | AW11: 0 | AX11: MCQ | BB11: CBSE | BC11: Mysore | BD11: Karnataka | BE11: South | BF11: Karnataka/Kerala | BG11: National Sales | BH11: 2024-04-01 00:00:00 | BI11: 2025-03-31 00:00:00 | BJ11: Regular School: Active school with student count and rate per student defined | BK11: 22028000021773164 | BL11: 51788000002731894 | BM11: zcrm_51788000266114662 | BN11: 2024-03-27 00:00:00 | BO11: aji.thomas_eiindia | BP11: sourabh.mehta_eiindia | BQ11: aji.thomas@ei.study | BR11: Aji thomas | BS11: Mohammadi Zohra | BT11: Mohammadi Zohra | BU11: 2024-05-09 11:10:39 | BV11: Mrs. HARSHIDA HARIKUMAR | BW11: Principal | BX11: harshida@pushkarinimys.com | BY11: +918971180000 | BZ11: mpvmysore@yahoo.com | CA11: Mrs. HARSHIDA HARIKUMAR | CB11: harshida@pushkarinimys.com | CC11: +918971180000 | CD11: Hemalatha | CE11: latha7179@yahoo.in | CF11: +919886079179 | CG11: 4000 | CH11: Vijayanagar 2Nd Stage Mysore Karnataka | CJ11: 570017 | CK11: Vijayanagar 2Nd Stage Mysore Karnataka | CL11: Mysore | CM11: Karnataka | CN11: 570017 | CP11: Vijayanagar 2Nd Stage Mysore Karnataka | CQ11: Vijayanagar 2Nd Stage Mysore Karnataka
A12: Key Account | B12: 110298 | C12: Platinum Jubilee High School | E12: Dropped | F12: 2024 | G12: 2024-10-22 00:00:00 | H12: Ei ASSET | I12: Regular | J12: IN-2022002536 | K12: Approved By Logistic Team | L12: 0 | M12: 0 | N12: 0 | O12: 701 | P12: 0 | Q12: 0 | R12: 0 | T12: 0 | U12: 0 | W12: 0 | X12: Full Payment | Z12: 2024-10-23 00:00:00 | AA12: 2000-01-01 00:00:00 | AB12: 0 | AC12: 2000-01-01 00:00:00 | AD12: 0 | AE12: 2000-01-01 00:00:00 | AF12: 0 | AG12: 2000-01-01 00:00:00 | AH12: 0 | AI12: 0 | AL12: 0 | AM12: 0 | AN12: 0 | AO12: 1 | AP12: 1 | AU12: Winter Round | AV12: OMR | AW12: 0 | AX12: MCQ | BB12: State Board | BC12: Warangal | BD12: Telangana | BE12: South | BF12: AP/Telangana | BG12: National Sales | BH12: 2024-09-01 00:00:00 | BI12: 2025-03-31 00:00:00 | BJ12: Regular School: Active school with student count and rate per student defined | BK12: 22028000025644064 | BL12: 51788000002732015 | BM12: zcrm_51788000274553290 | BN12: 2024-10-22 00:00:00 | BO12: maruf.shaikh1 | BP12: maruf.shaikh1 | BQ12: maruf.shaikh@ei.study | BR12: Maruf shaikh | BS12: Manjeetsingh Ladhad | BU12: 2024-10-22 12:55:58 | BV12: Jagdish Peche | BW12: Principal | BX12: jagdish.peche@akesi.org | BY12: +919652313666 | CA12: Jagdish Peche | CB12: jagdish.peche@akesi.org | CC12: +919652313666 | CD12: Prasanna | CE12: jagdish.peche@akesi.org | CF12: +916303627829 | CG12: 0 | CH12: 16-8-19/1, Fort Road Abbani Kunta Warangal Telangana INDIA | CJ12: 506002 | CK12: 16-8-19/1, Fort Road Abbani Kunta Warangal Telangana INDIA | CL12: Warangal | CM12: Telangana | CN12: 506002 | CP12: 16-8-19/1, Fort Road Abbani Kunta Warangal Telangana INDIA | CQ12: 16-8-19/1, Fort Road Abbani Kunta Warangal Telangana INDIA
A13: Retention School | B13: 1131322 | C13: The Global Edge School | F13: 2024 | G13: 2024-04-05 00:00:00 | H13: Ei ASSET | I13: Regular | J13: IN-2022001858 | K13: Approved By Logistic Team | L13: 380190 | M13: 380190 | N13: 380190 | O13: 667 | P13: 570 | Q13: 0 | R13: 0 | T13: 0 | U13: 0 | W13: 0 | X13: Full Payment | Z13: 2024-07-31 00:00:00 | AA13: 2000-01-01 00:00:00 | AB13: 0 | AC13: 2000-01-01 00:00:00 | AD13: 0 | AE13: 2000-01-01 00:00:00 | AF13: 0 | AG13: 2000-01-01 00:00:00 | AH13: 0 | AI13: 38019 | AJ13: 2024-09-23 00:00:00 | AK13: 2024-09-23 00:00:00 | AL13: 380190 | AM13: 342171 | AN13: 0 | AO13: 0.62 | AP13: 0.62 | AU13: Summer Round | AV13: OMR | AW13: 0 | AX13: MCQ | BB13: CBSE | BC13: Hyderabad | BD13: Telangana | BE13: South | BF13: AP/Telangana | BG13: National Sales | BH13: 2024-06-01 00:00:00 | BI13: 2025-03-31 00:00:00 | BJ13: Regular School: Active school with student count and rate per student defined | BK13: 22028000021930452 | BL13: 51788000002749196 | BM13: zcrm_51788000266680049 | BN13: 2024-04-05 00:00:00 | BO13: chaitanya.kolluri_ei | BP13: hakim.kanchwala_eiindia1 | BQ13: chaitanya.kolluri@ei.study | BR13: Chaitanya kolluri | BS13: Jasper Jessie | BU13: 2024-04-24 10:20:43 | BV13: Ms, Swathi Reddy | BW13: School Owner | BX13: accountsincharge@globaledgeschool.com | BY13: +919640551155 | CA13: Ms. Anju Madan | CB13: principal@globaledgeschool.com | CD13: Ms.Anitha Jha | CE13: anithajha@globaledgeschool.com | CF13: +919052424441 | CG13: 0 | CH13: Plot no. 8/A,Part of Survey no.s 74 and 75,Jai Hind Enclave,100 feet road,Madhapur | CJ13: 500081 | CK13: Plot no. 8/A,Part of Survey no.s 74 and 75,Jai Hind Enclave,100 feet road,Madhapur | CL13: Hyderabad | CM13: Telangana | CN13: 500081 | CO13: HYDM04246E | CP13: Plot no. 8/A,Part of Survey no.s 74 and 75,Jai Hind Enclave,100 feet road,Madhapur | CQ13: Plot no. 8/A,Part of Survey no.s 74 and 75,Jai Hind Enclave,100 feet road,Madhapur
A14: New School | B14: 1134175 | C14: St. Mary Champion H.Sec. School | E14: Dropped | F14: 2024 | G14: 2024-02-20 00:00:00 | H14: Ei CARES | I14: Regular | J14: IN-2022001530 | K14: Approved By Logistic Team | L14: 468000 | M14: 468000 | N14: 0 | O14: 0 | Q14: 468000 | R14: 300 | S14: 1560 | T14: 0 | U14: 0 | W14: 0 | X14: Installments | Y14: 3 | AA14: 2024-03-15 00:00:00 | AB14: 140400 | AC14: 2024-09-02 00:00:00 | AD14: 163800 | AE14: 2024-12-31 00:00:00 | AF14: 163800 | AG14: 2000-01-01 00:00:00 | AH14: 0 | AI14: 45436 | AJ14: 2024-03-04 00:00:00 | AK14: 2025-01-10 00:00:00 | AL14: 468000 | AM14: 408915 | AN14: 13649 | AO14: 0.4 | AP14: 0.4 | AU14: 0 | AW14: 4 | AX14: MCQ | AY14: Printing By EI | AZ14: OMR | BB14: CBSE | BC14: Indore | BD14: Madhya Pradesh | BE14: North | BF14: MP/Chattisgarh | BG14: National Sales | BH14: 2024-04-02 00:00:00 | BI14: 2025-03-29 00:00:00 | BJ14: Regular School: Active school with student count and rate per student defined | BK14: 22028000021136288 | BL14: 51788000002749223 | BM14: zcrm_51788000254781412 | BN14: 2024-02-20 00:00:00 | BO14: Laxminarayan Dogayan | BP14: fagun.saraiya_eiindia1 | BQ14: laxminarayan.dogayan@ei.study | BR14: Laxminarayan dogayan | BS14: Laxminarayan Dogayan | BT14: Shruti Chauhan | BU14: 2024-02-23 10:37:00 | BV14: Mr. Victor Swamy | BW14: Admin | BX14: victor.swamy@gmail.con | BY14: +917389623616 | BZ14: principal_smchss@yahoo.com | CG14: 50000 | CH14: Suryadev Nagar, Gopur Square | CJ14: 452009 | CK14: Suryadev Nagar, Gopur Square | CL14: Indore | CM14: Madhya Pradesh | CN14: 452009 | CO14: BPLS14197B | CP14: Suryadev Nagar, Gopur Square | CQ14: Suryadev Nagar, Gopur Square
A15: Retention School | B15: 1163014 | C15: Vidya Devi Jindal School | D15: =VLOOKUP(B15,'2025'!B:C,2,0) -> Sudhi | F15: 2024 | G15: 2024-04-04 00:00:00 | H15: Ei ASSET, Ei Mindspark | I15: Regular | J15: IN-2022001842, IN-2022001843, IN-2022001844 | K15: Approved By Logistic Team | L15: 1664554 | M15: 1752664 | N15: 1175052 | O15: 854 | P15: 1376 | Q15: 0 | R15: 0 | T15: 489502 | U15: 210 | V15: 2331 | W15: 0 | X15: Full Payment | Z15: 2024-04-06 00:00:00 | AA15: 2000-01-01 00:00:00 | AB15: 0 | AC15: 2000-01-01 00:00:00 | AD15: 0 | AE15: 2000-01-01 00:00:00 | AF15: 0 | AG15: 2000-01-01 00:00:00 | AH15: 0 | AI15: 0 | AJ15: 2024-05-03 00:00:00 | AK15: 2024-05-03 00:00:00 | AL15: 577612, 587526 | AM15: 0, 490970, 885728 | AN15: -298202, 587526, 86642 | AO15: 0.4462, 0.618 | AP15: 0.4462, 0.618 | AU15: 0, Summer Round, Winter Round | AV15: OMR | AW15: 0 | AX15: MCQ | BA15: Online | BB15: CBSE | BC15: Hisar | BD15: Haryana | BE15: North | BF15: Delhi/Haryana | BG15: National Sales | BH15: 2024-04-04 00:00:00 | BI15: 2025-03-31 00:00:00 | BJ15: Regular School: Active school with student count and rate per student defined | BK15: 22028000021909640, 22028000021909708, 22028000021909804 | BL15: 51788000002749807 | BM15: zcrm_51788000267810265, zcrm_51788000267810442, zcrm_51788000267810619 | BN15: 2024-04-04 00:00:00 | BO15: virender.verma_ei | BP15: fagun.saraiya_eiindia1 | BQ15: virender.verma@ei.study | BR15: Virender verma | BS15: Bhavishya Bansal | BU15: 2024-04-05 15:50:53, 2024-04-05 15:51:33, 2024-04-05 15:52:04 | BV15: Ms. Kamalica Bhowmick | BW15: Other | BX15: doac@vdjs.edu.in | BY15: +919831461183 | BZ15: info@vdjs.edu.in | CG15: 0 | CH15: Hisar-Delhi Bypass Rd, Hisar Cantt, Hisar, Haryana 125044 | CJ15: 125044 | CK15: Hisar-Delhi Bypass Rd, Hisar Cantt, Hisar, Haryana 125044 | CL15: Hisar | CM15: Haryana | CN15: 125044 | CO15: RTKV01058B | CP15: Hisar-Delhi Bypass Rd, Hisar Cantt, Hisar, Haryana 125044 | CQ15: Hisar-Delhi Bypass Rd, Hisar Cantt, Hisar, Haryana 125044
A16: Retention School | B16: 1204891 | C16: B.K Birla Public School, Kalyan | D16: =VLOOKUP(B16,'2025'!B:C,2,0) -> Saloni Shah | F16: 2024 | G16: 2024-06-08 00:00:00, 2024-07-04 00:00:00 | H16: Ei ASSET, Ei Mindspark | I16: Regular | J16: IN-2022002186, IN-2022002308 | K16: Approved By Logistic Team | L16: 2202356 | M16: 2359020 | N16: 1332000 | O16: 2220 | P16: 600 | Q16: 0 | R16: 0 | T16: 870356 | U16: 395 | V16: 2203 | W16: 0 | X16: Installments | Y16: 2 | AA16: 2024-06-10 00:00:00, 2024-07-04 00:00:00 | AB16: 256755, 333000 | AC16: 2024-07-31 00:00:00, 2024-10-31 00:00:00 | AD16: 770265, 999000 | AE16: 2000-01-01 00:00:00 | AF16: 0 | AG16: 2000-01-01 00:00:00 | AH16: 0 | AI16: 133200, 78716 | AJ16: 2024-06-14 00:00:00, 2024-08-16 00:00:00 | AK16: 2024-11-07 00:00:00, 2025-02-21 00:00:00 | AL16: 1027020, 1332000 | AM16: 1198800, 754879 | AN16: 0, 193425 | AO16: 0.2778, 0.6 | AP16: 0.2778, 0.6 | AU16: 0, Winter Round | AV16: OMR | AW16: 0 | AX16: MCQ | BA16: Online | BB16: CBSE | BC16: Kalyan | BD16: Maharashtra | BE16: West | BF16: Mumbai | BG16: National Sales | BH16: 2024-06-01 00:00:00, 2024-06-08 00:00:00 | BI16: 2025-05-31 00:00:00 | BJ16: Regular School: Active school with student count and rate per student defined | BK16: 22028000022859928, 22028000023342260 | BL16: 51788000002750595 | BM16: zcrm_51788000270447061, zcrm_51788000271386001 | BN16: 2024-06-08 00:00:00, 2024-07-04 00:00:00 | BO16: hetal.parmar_ei | BP16: fagun.saraiya_eiindia1 | BQ16: hetal.parmar@ei.study | BR16: Hetal parmar | BS16: Saloni Shah | BU16: 2024-06-08 17:38:19, 2024-07-13 18:19:51 | BV16: Ms. Ruchita . | BX16: viceprincipal@birlaschoolkalyan.com | BY16: +919820776655 | BZ16: contact@birlaschoolkalyan.com | CA16: Ms.Ruchita | CB16: viceprincipal@birlaschoolkalyan.com | CC16: +919820776655 | CD16: Ms.Ruchita | CE16: viceprincipal@birlaschoolkalyan.com | CF16: +919820776655 | CG16: 0 | CH16: B K Birla College Road, Near Rto, Kalyan West, | CJ16: 421304 | CK16: B K Birla College Road, Near Rto, Kalyan West, | CL16: Kalyan | CM16: Maharashtra | CN16: 421304 | CO16: PNEK06448B | CP16: B K Birla College Road, Near Rto, Kalyan West, | CQ16: B K Birla College Road, Near Rto, Kalyan West,
A17: Retention School | B17: 12539 | C17: Mahadevi Birla World Academy (Junior Wing) | D17: =VLOOKUP(B17,'2025'!B:C,2,0) -> Lopamudra Das | F17: 2024 | G17: 2024-02-21 00:00:00 | H17: Ei CARES, Ei Mindspark | I17: Regular | J17: IN-2022001540, IN-2022001541 | K17: Approved By Logistic Team | L17: 3166135 | M17: 3582955 | N17: 0 | O17: 0 | Q17: 850468 | R17: 630 | S17: 1350 | T17: 2315667 | U17: 1035 | V17: 2237 | W17: 0 | X17: Installments | Y17: 2 | AA17: 2024-03-30 00:00:00 | AB17: 1366244, 425234 | AC17: 2024-09-30 00:00:00 | AD17: 1366244, 425234 | AE17: 2000-01-01 00:00:00 | AF17: 0 | AG17: 2000-01-01 00:00:00 | AH17: 0 | AI17: 24654, 40518 | AJ17: 2024-04-02 00:00:00, 2024-10-23 00:00:00 | AK17: 2024-10-23 00:00:00 | AL17: 2732488, 850468 | AM17: 1429960.21, 2193743.31 | AN17: -1383793, 1277874 | AO17: 0.5926, 0.6143 | AP17: 0.5926, 0.6143 | AU17: 0 | AW17: 0, 4 | AX17: MCQ | AY17: Printing By EI | AZ17: OMR | BA17: Online | BB17: CBSE | BC17: Kolkata | BD17: West Bengal | BE17: East | BF17: West Bengal | BG17: National Sales | BH17: 2024-04-02 00:00:00, 2024-04-15 00:00:00 | BI17: 2025-03-27 00:00:00, 2025-03-31 00:00:00 | BJ17: Regular School: Active school with student count and rate per student defined | BK17: 22028000021161100, 22028000021161152 | BL17: 51788000002728599 | BM17: zcrm_51788000265501025, zcrm_51788000265501166 | BN17: 2024-02-21 00:00:00 | BO17: lopamudra.das_eiindia1 | BP17: mitul.patel_ei1 | BQ17: lopamudra.das@ei.study | BR17: Lopamudra das | BS17: Lopamudra Das | BU17: 2024-03-19 10:01:07, 2024-03-19 15:05:15 | BV17: Mr. Vikram Ruia | BX17: administrator@mbwa.org.in | BY17: +919830295876 | BZ17: principal@mbwa.org.in | CA17: Ms Anjana Saha | CB17: principal@mbwa.org.in | CD17: Basundhara Bhattacharya (CARES) | CE17: coordinator.mid@mbwa.org.in | CF17: +919903595193 | CG17: 0 | CH17: 17 A, Darga Road, Park Circus | CJ17: 700017 | CK17: 17 A, Darga Road, Park Circus | CL17: Kolkata | CM17: West Bengal | CN17: 700017 | CO17: CALM01347D | CP17: 17 A, Darga Road, Park Circus | CQ17: 17 A, Darga Road, Park Circus
A18: New School | B18: 1271232 | C18: Rishikul Vidyapeeth, Rishikul Vidyapeeth School | D18: =VLOOKUP(B18,'2025'!B:C,2,0) -> Sudhi | F18: 2024 | G18: 2024-02-25 00:00:00, 2025-05-06 00:00:00 | H18: Ei ASSET, Ei CARES | I18: Group School - Centralize Invoicing | J18: IN-2022001549, IN-2022003466 | K18: Approved By Logistic Team | L18: 1648206 | M18: 1648206 | N18: 0 | O18: 346 | P18: 0 | Q18: 1648206 | R18: 1030 | S18: 1600 | T18: 0 | U18: 0 | W18: 0 | X18: Full Payment, Installments | Y18: 2 | Z18: 2024-12-30 00:00:00 | AA18: 2000-01-01 00:00:00, 2024-04-15 00:00:00 | AB18: 0, 824103 | AC18: 2000-01-01 00:00:00, 2024-08-16 00:00:00 | AD18: 0, 824103 | AE18: 2000-01-01 00:00:00 | AF18: 0 | AG18: 2000-01-01 00:00:00 | AH18: 0 | AI18: 0 | AJ18: 2024-02-23 00:00:00 | AK18: 2024-11-20 00:00:00 | AL18: 0, 1648206 | AM18: 0, 720090 | AN18: 0, 928116 | AO18: 0.5428000000000001, 1 | AP18: 0.4928, 1 | AR18: 0.05 | AU18: 0, Winter Round | AV18: OMR | AW18: 0, 4 | AX18: MCQ | AY18: Printing By EI | AZ18: OMR | BB18: CBSE | BC18: Sonepat | BD18: Haryana | BE18: North | BF18: Delhi/Haryana | BG18: National Sales | BH18: 2024-04-01 00:00:00 | BI18: 2025-03-31 00:00:00 | BJ18: Regular School: Active school with student count and rate per student defined | BK18: 22028000021209392, 22028000029865060 | BL18: 51788000002751831 | BM18: zcrm_51788000255131686, zcrm_51788000288555651 | BN18: 2024-02-25 00:00:00, 2025-05-06 00:00:00 | BO18: vikas.shukla_ei | BP18: fagun.saraiya_eiindia1, maruf.shaikh1 | BQ18: vikas.shukla@ei.study | BR18: Vikas shukla | BS18: Sudhi Malhotra | BU18: 2024-03-02 10:52:25, 2025-05-06 10:30:49 | BV18: Dheeraj Sharma | BW18: School Owner | BX18: Dheeraj.sharma@rishikulvidyapeeth.edu.in, dheeraj.sharma@rishikulvidyapeeth.edu.in | BY18: +919991114140 | BZ18: dheeraj.sharma@rishikulvidyapeeth.edu.in | CA18: Dheeraj Sharma | CB18: dheeraj.sharma@rishikulvidyapeeth.edu.in, dheerajsharma@rishikulvidyapeeth.edu.in | CC18: +919991114140 | CD18: Dheeraj Sharma, Nisha | CE18: dheerajsharma@rishikulvidyapeeth.edu.in, nisha@rishikulvidyapeeth.edu.in | CF18: +919416524444, +919991114140 | CG18: 44000 | CH18: Devru Road, Devru Road, Jeeva vihar | CJ18: 131001 | CK18: Devru Road, Jeeva vihar, Devru Road, Jeevan Vihar | CL18: Sonepat | CM18: Haryana | CN18: 131001 | CP18: Devru Road, Jeeva vihar | CQ18: Devru Road, Jeevan Vihar
A19: Key Account | B19: 128171 | C19: Navrachana School, Sama | D19: =VLOOKUP(B19,'2025'!B:C,2,0) -> Ishita Jethwa | F19: 2024 | G19: 2024-04-16 00:00:00 | H19: Ei CARES | I19: Regular | J19: IN-2022001918 | K19: Approved By Logistic Team | L19: 1797563 | M19: 1797563 | N19: 0 | O19: 0 | Q19: 1797563 | R19: 1924 | S19: 934 | T19: 0 | U19: 0 | W19: 0 | X19: Installments | Y19: 2 | AA19: 2024-04-20 00:00:00 | AB19: 898782 | AC19: 2024-11-01 00:00:00 | AD19: 898782 | AE19: 2000-01-01 00:00:00 | AF19: 0 | AG19: 2000-01-01 00:00:00 | AH19: 0 | AI19: 35868 | AJ19: 2024-06-28 00:00:00 | AK19: 2024-11-26 00:00:00 | AL19: 1797564 | AM19: 1757508 | AN19: 4188 | AO19: 0.7137 | AP19: 0.6137 | AR19: 0.05 | AT19: 0.05 | AU19: 0 | AW19: 4 | AX19: MCQ | AY19: Printing By EI | AZ19: OMR | BB19: CBSE | BC19: Vadodara | BD19: Gujarat | BE19: West | BF19: Gujarat | BG19: National Sales | BH19: 2024-04-01 00:00:00 | BI19: 2025-03-31 00:00:00 | BJ19: Regular School: Active school with student count and rate per student defined | BK19: 22028000022100080 | BL19: 51788000002732079 | BM19: zcrm_51788000267509650 | BN19: 2024-04-16 00:00:00 | BO19: heena.kumar_ei | BP19: fagun.saraiya_eiindia1 | BQ19: heena.kumar@ei.study | BR19: Heena kumar | BS19: Heena Kumar | BU19: 2024-05-03 10:58:47 | BV19: Ms. Suprabha Menon | BW19: Principal | BX19: suprabham@navrachana.edu.in | BY19: +919925260895 | BZ19: navrachanasama@navrachana.edu.in | CA19: Ms. Suprabha Menon | CB19: suprabham@navrachana.edu.in | CC19: +919925260895 | CD19: Ms. Gayatri Devliyal | CE19: gayatrid@navrachana.edu.in | CF19: +917016014240 | CG19: 100300 | CH19: Sama Road | CJ19: 390024 | CK19: Sama Road, Near GIPCL Circle | CL19: Vadodara | CM19: Gujarat | CN19: 390024 | CO19: BRDN01995A | CP19: Sama Road | CQ19: Sama Road, Near GIPCL Circle
A20: Retention School | B20: 1312595 | C20: KLE M. R. Sakhare State School, Hubballi | F20: 2024 | G20: 2024-06-16 00:00:00 | H20: Ei ASSET, Ei Mindspark | I20: Regular | J20: IN-2022002212, IN-2022002236 | K20: Approved By Logistic Team | L20: 440692 | M20: 490128 | N20: 166047 | O20: 534 | P20: 311 | Q20: 0 | R20: 0 | T20: 274645 | U20: 540 | V20: 509 | W20: 0 | X20: Installments | Y20: 2 | AA20: 2024-07-15 00:00:00 | AB20: 162041, 83024 | AC20: 2024-11-15 00:00:00, 2024-12-15 00:00:00 | AD20: 162041, 83024 | AE20: 2000-01-01 00:00:00 | AF20: 0 | AG20: 2000-01-01 00:00:00 | AH20: 0 | AI20: 16794, 27458 | AJ20: 2024-09-05 00:00:00, 2024-09-18 00:00:00 | AK20: 2025-01-17 00:00:00 | AL20: 166048, 324082 | AM20: 151146, 296544 | AN20: -1892, 80 | AO20: 0.7927, 0.8332999999999999 | AP20: 0.7927, 0.8332999999999999 | AU20: 0, Winter Round | AV20: OMR | AW20: 0 | AX20: MCQ | BA20: Offline | BB20: State Board | BC20: Hubli | BD20: Karnataka | BE20: South | BF20: Karnataka/Kerala | BG20: National Sales | BH20: 2024-06-01 00:00:00 | BI20: 2025-04-30 00:00:00, 2025-05-31 00:00:00 | BJ20: Regular School: Active school with student count and rate per student defined | BK20: 22028000023002488, 22028000023033448 | BL20: 51788000002752617 | BM20: zcrm_51788000270598683, zcrm_51788000270690525 | BN20: 2024-06-16 00:00:00 | BO20: vineet.upadhye_ei | BP20: mitul.patel_ei1 | BQ20: vineet.upadhye@ei.study | BR20: Vineet upadhye | BS20: Nisha Murali | BU20: 2024-06-18 10:43:12, 2024-06-18 10:43:30 | BV20: Maruf Shaikh | BX20: maruf.shaikh@ei.study | BY20: +919016039311 | BZ20: klemrsakharestate@gmail.com | CG20: 0 | CH20: Vidyanagar, Hubballi, Unkal Cross | CJ20: 580031 | CK20: Vidyanagar, Hubballi, Unkal Cross | CL20: Hubli | CM20: Karnataka | CN20: 580031 | CO20: BLRK04875D | CP20: Vidyanagar, Hubballi, Unkal Cross | CQ20: Vidyanagar, Hubballi, Unkal Cross
A21: Retention School | B21: 1315210 | C21: KLE School, Manjunath Nagar, Hubballi | F21: 2024 | G21: 2024-06-16 00:00:00 | H21: Ei ASSET, Ei Mindspark | I21: Regular | J21: IN-2022002214, IN-2022002235 | K21: Approved By Logistic Team | L21: 610369 | M21: 678481 | N21: 231969 | O21: 746 | P21: 311 | Q21: 0 | R21: 0 | T21: 378400 | U21: 744 | V21: 509 | W21: 0 | X21: Installments | Y21: 2 | AA21: 2024-07-15 00:00:00 | AB21: 115985, 223256 | AC21: 2024-11-15 00:00:00, 2024-12-15 00:00:00 | AD21: 115985, 223256 | AE21: 2000-01-01 00:00:00 | AF21: 0 | AG21: 2000-01-01 00:00:00 | AH21: 0 | AI21: 23325, 38136 | AJ21: 2024-09-05 00:00:00, 2024-09-18 00:00:00 | AK21: 2025-01-17 00:00:00 | AL21: 231970, 446512 | AM21: 209925, 411864 | AN21: -1280, -3488 | AO21: 0.7927, 0.8332999999999999 | AP21: 0.7927, 0.8332999999999999 | AU21: 0, Winter Round | AV21: OMR | AW21: 0 | AX21: MCQ | BA21: Online | BB21: CBSE | BC21: Hubli | BD21: Karnataka | BE21: South | BF21: Karnataka/Kerala | BG21: National Sales | BH21: 2024-06-01 00:00:00 | BI21: 2025-04-30 00:00:00, 2025-05-31 00:00:00 | BJ21: Regular School: Active school with student count and rate per student defined | BK21: 22028000023002568, 22028000023033408 | BL21: 51788000002752639 | BM21: zcrm_51788000270598543, zcrm_51788000270633910 | BN21: 2024-06-16 00:00:00 | BO21: vineet.upadhye_ei | BP21: mitul.patel_ei1 | BQ21: vineet.upadhye@ei.study | BR21: Vineet upadhye | BS21: Nisha Murali | BU21: 2024-06-18 10:42:47, 2024-06-18 10:44:49 | BV21: Maruf Shaikh | BX21: maruf.shaikh@ei.study | BY21: +919016039311 | BZ21: kleschool_man@yahoo.com | CG21: 0 | CH21: Gokul Road, Manjunath Nagar, | CJ21: 580030 | CK21: Gokul Road, Manjunath Nagar, HUBBALLI | CL21: Hubli | CM21: Karnataka | CN21: 580030 | CO21: BLRK04875D | CP21: Gokul Road, Manjunath Nagar, | CQ21: Gokul Road, Manjunath Nagar, HUBBALLI
A22: Retention School | B22: 1316481 | C22: KLE School, Gadag | F22: 2024 | G22: 2024-06-16 00:00:00 | H22: Ei ASSET, Ei Mindspark | I22: Regular | J22: IN-2022002216, IN-2022002232 | K22: Approved By Logistic Team | L22: 684044 | M22: 760212 | N22: 260887 | O22: 839 | P22: 311 | Q22: 0 | R22: 0 | T22: 423157 | U22: 832 | V22: 509 | W22: 0 | X22: Installments | Y22: 2 | AA22: 2024-07-15 00:00:00 | AB22: 130444, 249663 | AC22: 2024-11-15 00:00:00, 2024-12-15 00:00:00 | AD22: 130444, 249663 | AE22: 2000-01-01 00:00:00 | AF22: 0 | AG22: 2000-01-01 00:00:00 | AH22: 0 | AI22: 26061.8, 42610 | AJ22: 2024-09-05 00:00:00, 2024-09-18 00:00:00 | AK22: 2025-01-17 00:00:00 | AL22: 260888, 499326 | AM22: 234556.2, 460190 | AN22: -3474, 270 | AO22: 0.7927, 0.8332999999999999 | AP22: 0.7927, 0.8332999999999999 | AU22: 0, Winter Round | AV22: OMR | AW22: 0 | AX22: MCQ | BA22: Offline | BB22: CBSE | BC22: Gadag | BD22: Karnataka | BE22: South | BF22: Karnataka/Kerala | BG22: National Sales | BH22: 2024-06-01 00:00:00 | BI22: 2025-04-30 00:00:00, 2025-05-31 00:00:00 | BJ22: Regular School: Active school with student count and rate per student defined | BK22: 22028000023002648, 22028000023033288 | BL22: 51788000002752651 | BM22: zcrm_51788000270598125, zcrm_51788000270633787 | BN22: 2024-06-16 00:00:00 | BO22: vineet.upadhye_ei | BP22: mitul.patel_ei1 | BQ22: vineet.upadhye@ei.study | BR22: Vineet upadhye | BS22: Nisha Murali | BU22: 2024-06-18 10:40:44, 2024-06-18 10:48:43 | BV22: Maruf Shaikh | BX22: maruf.shaikh@ei.study | BY22: +919016039311 | BZ22: klesgdg@gmail.com | CG22: 0 | CH22: J T College Campus, Hatalgeri Naka Gadag | CJ22: 582101 | CK22: J T College Campus, Hatalgeri Naka Gadag | CL22: Gadag | CM22: Karnataka | CN22: 582101 | CO22: BLRK04875D | CP22: J T College Campus, Hatalgeri Naka Gadag | CQ22: J T College Campus, Hatalgeri Naka Gadag
A23: New School | B23: 1324480 | C23: The Century School | D23: =VLOOKUP(B23,'2025'!B:C,2,0) -> Tanya | F23: 2024 | G23: 2024-06-07 00:00:00, 2024-11-20 00:00:00 | H23: Ei ASSET, Ei Mindspark | I23: Regular | J23: IN-2022002178, IN-2022002609 | K23: Approved By Logistic Team | L23: 1282258 | M23: 1450060 | N23: 350025 | O23: 500 | P23: 700 | Q23: 0 | R23: 0 | T23: 932233 | U23: 500 | V23: 1864 | W23: 0 | X23: Installments | Y23: 2, 4 | AA23: 2024-06-15 00:00:00, 2024-11-30 00:00:00 | AB23: 175013, 275009 | AC23: 2024-08-31 00:00:00, 2024-12-10 00:00:00 | AD23: 175013, 275009 | AE23: 2000-01-01 00:00:00, 2024-10-31 00:00:00 | AF23: 0, 275009 | AG23: 2000-01-01 00:00:00, 2024-12-31 00:00:00 | AH23: 0, 275009 | AI23: 0 | AJ23: 2024-07-19 00:00:00, 2024-11-30 00:00:00 | AK23: 2024-12-31 00:00:00, 2025-05-13 00:00:00 | AL23: 1100036, 350026 | AM23: 200000, 958832 | AN23: 141204, 150026 | AO23: 0.3889, 0.5333 | AP23: 0.3889, 0.5333 | AU23: 0, Winter Round | AV23: OMR | AW23: 0 | AX23: MCQ | BA23: Online | BB23: CBSE | BC23: Karnal | BD23: Haryana | BE23: North | BF23: Delhi/Haryana | BG23: National Sales | BH23: 2024-03-01 00:00:00, 2024-06-24 00:00:00 | BI23: 2025-03-31 00:00:00 | BJ23: Regular School: Active school with student count and rate per student defined | BK23: 22028000022873236, 22028000026329168 | BL23: 51788000002752831 | BM23: zcrm_51788000270363462, zcrm_51788000277767578 | BN23: 2024-06-07 00:00:00, 2024-11-20 00:00:00 | BO23: vikas.shukla_ei | BP23: fagun.saraiya_eiindia1 | BQ23: vikas.shukla@ei.study | BR23: Vikas shukla | BS23: Vikas Shukla | BT23: Tanya Marina Brooks | BU23: 2024-06-12 11:51:42, 2024-12-02 10:19:54 | BV23: Mr. Ankur Jindal | BW23: School Owner | BX23: director@thecenturyschool.com | BY23: +919416032976 | BZ23: thecenturyschool@rediffmail.com | CA23: Dr. Karuna Arora | CB23: drkarunaarora@gmail.com | CC23: +919416266294 | CD23: Dr. Karuna Arora | CE23: drkarunaarora@gmail.com | CF23: +919416266294 | CG23: 8000 | CH23: G T Road Karnal Side Gharaunda Distt Karnal Haryana | CJ23: 132114 | CK23: G T Road Karnal Side Gharaunda Distt Karnal Haryana | CL23: Karnal | CM23: Haryana | CN23: 132114 | CP23: G T Road Karnal Side Gharaunda Distt Karnal Haryana | CQ23: G T Road Karnal Side Gharaunda Distt Karnal Haryana
A24: Retention School | B24: 1330320 | C24: KLE Mahadevappanna Munavalli School, Gokak | F24: 2024 | G24: 2024-06-16 00:00:00 | H24: Ei ASSET, Ei Mindspark | I24: Regular | J24: IN-2022002215, IN-2022002233 | K24: Approved By Logistic Team | L24: 753983 | M24: 840222 | N24: 274880 | O24: 884 | P24: 311 | Q24: 0 | R24: 0 | T24: 479103 | U24: 942 | V24: 509 | W24: 0 | X24: Installments | Y24: 2 | AA24: 2024-07-15 00:00:00 | AB24: 137440, 282671 | AC24: 2024-11-15 00:00:00, 2024-12-15 00:00:00 | AD24: 137440, 282671 | AE24: 2000-01-01 00:00:00 | AF24: 0 | AG24: 2000-01-01 00:00:00 | AH24: 0 | AI24: 27803.4, 45458 | AJ24: 2024-09-05 00:00:00, 2024-09-18 00:00:00 | AK24: 2025-01-17 00:00:00 | AL24: 274880, 565342 | AM24: 250230.6, 490942 | AN24: -3154, 28942 | AO24: 0.7927, 0.8332999999999999 | AP24: 0.7927, 0.8332999999999999 | AU24: 0, Winter Round | AV24: OMR | AW24: 0 | AX24: MCQ | BA24: Online | BB24: CBSE | BC24: Gokak | BD24: Karnataka | BE24: South | BF24: Karnataka/Kerala | BG24: National Sales | BH24: 2024-06-01 00:00:00 | BI24: 2025-04-30 00:00:00, 2025-05-31 00:00:00 | BJ24: Regular School: Active school with student count and rate per student defined | BK24: 22028000023002608, 22028000023033328 | BL24: 51788000002752887 | BM24: zcrm_51788000270598265, zcrm_51788000270690263 | BN24: 2024-06-16 00:00:00 | BO24: vineet.upadhye_ei | BP24: mitul.patel_ei1 | BQ24: vineet.upadhye@ei.study | BR24: Vineet upadhye | BS24: Nisha Murali | BU24: 2024-06-18 10:41:32, 2024-06-18 10:52:16 | BV24: Maruf Shaikh | BX24: maruf.shaikh@ei.study | BY24: +919016039311 | BZ24: klesgokak@gmail.com | CG24: 0 | CH24: Opp. Umrani^S Hospital, K.L.E. Campus Main Road, Dist. Gokak | CJ24: 591307 | CK24: Opp. Umrani^S Hospital, K.L.E. Campus Main Road, Dist. Gokak | CL24: Gokak | CM24: Karnataka | CN24: 591307 | CO24: BLRK04875D | CP24: Opp. Umrani^S Hospital, K.L.E. Campus Main Road, Dist. Gokak | CQ24: Opp. Umrani^S Hospital, K.L.E. Campus Main Road, Dist. Gokak
A25: Retention School | B25: 1337248 | C25: The Sivakasi Lions Matriculation Higher Secondary School | F25: 2024 | G25: 2024-06-03 00:00:00 | H25: Ei Mindspark | I25: Regular | J25: IN-2022002148 | K25: Approved By Logistic Team | L25: 480456 | M25: 566938 | N25: 0 | O25: 0 | Q25: 0 | R25: 0 | T25: 480456 | U25: 378 | V25: 1271 | W25: 0 | X25: Installments | Y25: 4 | AA25: 2024-06-05 00:00:00 | AB25: 141735 | AC25: 2024-09-10 00:00:00 | AD25: 141735 | AE25: 2024-12-10 00:00:00 | AF25: 141735 | AG25: 2024-12-31 00:00:00 | AH25: 141735 | AI25: 5306 | AJ25: 2024-06-13 00:00:00 | AK25: 2025-03-21 00:00:00 | AL25: 566940 | AM25: 570409 | AN25: -8775 | AO25: 0.5834 | AP25: 0.5834 | AU25: 0 | AW25: 0 | AX25: MCQ | BA25: Online | BB25: CBSE | BC25: Sivakasi | BD25: Tamil Nadu | BE25: South | BF25: Tamil Nadu | BG25: National Sales | BH25: 2024-06-05 00:00:00 | BI25: 2025-05-31 00:00:00 | BJ25: Regular School: Active school with student count and rate per student defined | BK25: 22028000022758828 | BL25: 51788000002753055 | BM25: zcrm_51788000270232074 | BN25: 2024-06-03 00:00:00 | BO25: vineeth.v_ei | BP25: hakim.kanchwala_eiindia1 | BQ25: vineeth.v@ei.study | BR25: Vineeth v | BS25: Vineeth T V | BU25: 2024-06-12 14:40:43 | BV25: Mr. Lion Ramesh Kumar J | BX25: correspondent@thesivakasilionsschool.in | BY25: +919486027172 | BZ25: principal@thesivakasilionsschool.in | CG25: 0 | CH25: 2/754-A Virudhunagar Road, Anaikuttam Post, Sivakasi | CJ25: 626189 | CK25: 2/754-A Virudhunagar Road, Anaikuttam Post, Sivakasi | CL25: Sivakasi | CM25: Tamil Nadu | CN25: 626189 | CO25: MRIT01544E | CP25: 2/754-A Virudhunagar Road, Anaikuttam Post, Sivakasi | CQ25: 2/754-A Virudhunagar Road, Anaikuttam Post, Sivakasi
A26: New School | B26: 14129 | C26: St. Hilda'S School | E26: Dropped | F26: 2024 | G26: 2023-11-23 00:00:00 | H26: Ei ASSET | I26: Regular | J26: IN-2022001289 | K26: Approved By Logistic Team | L26: 409200 | M26: 409200 | N26: 409200 | O26: 341 | P26: 1200 | Q26: 0 | R26: 0 | T26: 0 | U26: 0 | W26: 0 | X26: Installments | Y26: 2 | AA26: 2023-11-30 00:00:00 | AB26: 81840 | AC26: 2024-06-15 00:00:00 | AD26: 327360 | AE26: 2000-01-01 00:00:00 | AF26: 0 | AG26: 2000-01-01 00:00:00 | AH26: 0 | AI26: 0 | AJ26: 2023-12-05 00:00:00 | AK26: 2024-07-19 00:00:00 | AL26: 409200 | AM26: 404400 | AN26: 4800 | AO26: 0.2 | AP26: 0.2 | AU26: Summer Round | AV26: OMR | AW26: 0 | AX26: MCQ | BB26: CISCE | BC26: Ooty | BD26: Tamil Nadu | BE26: South | BF26: Tamil Nadu | BG26: National Sales | BH26: 2024-07-01 00:00:00 | BI26: 2024-07-31 00:00:00 | BJ26: Regular School: Active school with student count and rate per student defined | BK26: 22028000020060192 | BL26: 51788000002728613 | BM26: zcrm_51788000260939144 | BN26: 2023-11-23 00:00:00 | BO26: praveenkumar.rajamanickam_ei | BP26: sourabh.mehta_eiindia | BQ26: praveenkumar.rajamanickam@ei.study | BR26: Praveenkumar rajamanickam | BS26: Praveenkumar Rajamanickam | BT26: Dipti Jain | BU26: 2023-11-28 11:14:19 | BV26: Ms PAMELA RODRICKS . | BW26: Principal | BX26: sthildasprincipal@gmail.com | BY26: +919943241432 | BZ26: hildas_school@hotmail.com | CA26: Ms PAMELA RODRICKS . | CB26: sthildasprincipal@gmail.com | CC26: +919943241432 | CD26: Mr Ajay | CE26: sthildasprincipal@gmail.com | CF26: +919943241432 | CG26: 100000 | CH26: Sheddon Rd, Pudumund, Ooty, Tamil Nadu 643001 | CJ26: 643001 | CK26: Sheddon Rd, Pudumund, Ooty, Tamil Nadu 643001 | CL26: Ooty | CM26: Tamil Nadu | CN26: 643001 | CP26: Sheddon Rd, Pudumund, Ooty, Tamil Nadu 643001 | CQ26: Sheddon Rd, Pudumund, Ooty, Tamil Nadu 643001
A27: Retention School | B27: 1424516 | C27: JSS Public School, HSR Layout | F27: 2024 | G27: 2024-07-11 00:00:00 | H27: Ei ASSET | I27: Regular | J27: IN-2022002337 | K27: Approved By Logistic Team | L27: 911281 | M27: 911281 | N27: 911281 | O27: 1110 | P27: 821 | Q27: 0 | R27: 0 | T27: 0 | U27: 0 | W27: 0 | X27: Installments | Y27: 2 | AA27: 2024-07-31 00:00:00 | AB27: 273384 | AC27: 2024-11-30 00:00:00 | AD27: 637897 | AE27: 2000-01-01 00:00:00 | AF27: 0 | AG27: 2000-01-01 00:00:00 | AH27: 0 | AI27: 0 | AJ27: 2024-08-30 00:00:00 | AK27: 2025-05-31 00:00:00 | AL27: 911281 | AM27: 911280 | AN27: 1 | AO27: 0.5423 | AP27: 0.5423 | AU27: Winter Round | AV27: OMR | AW27: 0 | AX27: MCQ | BB27: CBSE | BC27: Bengaluru | BD27: Karnataka | BE27: South | BF27: Karnataka/Kerala | BG27: National Sales | BH27: 2024-08-01 00:00:00 | BI27: 2025-03-31 00:00:00 | BJ27: Regular School: Active school with student count and rate per student defined | BK27: 22028000023476100 | BL27: 51788000002754706 | BM27: zcrm_51788000271722001 | BN27: 2024-07-11 00:00:00 | BO27: dipti.jain_ei | BP27: mitul.patel_ei1 | BQ27: dipti.jain@ei.study | BR27: Dipti jain | BS27: Jasper Jessie | BU27: 2024-08-23 15:06:10 | BV27: Mrs. Lily Sahay | BW27: Principal | BX27: jss_hsrps@yahoo.com | BY27: +919731777112 | BZ27: jss_hsrps@yahoo.com | CG27: 0 | CH27: #4/A, 14Th Main, 6Th Sector, H.S.R. Layout, Adjacent To Bda Complex, | CJ27: 560102 | CK27: #4/A, 14Th Main, 6Th Sector, H.S.R. Layout, Adjacent To Bda Complex, | CL27: Bengaluru | CM27: Karnataka | CN27: 560102 | CP27: #4/A, 14Th Main, 6Th Sector, H.S.R. Layout, Adjacent To Bda Complex, | CQ27: #4/A, 14Th Main, 6Th Sector, H.S.R. Layout, Adjacent To Bda Complex,
A28: Retention School | B28: 1429114 | C28: Subbiah Central School | F28: 2024 | G28: 2024-06-17 00:00:00, 2024-06-24 00:00:00 | H28: Ei ASSET, Ei CARES | I28: Regular | J28: IN-2022002242, IN-2022002268, IN-2022002271 | K28: Approved By Logistic Team | L28: 1018600 | M28: 1018600 | N28: 269800 | O28: 284 | P28: 950 | Q28: 748800 | R28: 346 | S28: 1300, 2600 | T28: 0 | U28: 0 | W28: 0 | X28: Installments | Y28: 3, 4 | AA28: 2024-06-01 00:00:00, 2024-06-19 00:00:00 | AB28: 149500, 37700, 91732 | AC28: 2024-09-01 00:00:00, 2024-09-19 00:00:00 | AD28: 149500, 37700, 89034 | AE28: 2024-11-01 00:00:00, 2024-12-01 00:00:00 | AF28: 149500, 37700, 89034 | AG28: 2000-01-01 00:00:00, 2024-12-31 00:00:00 | AH28: 0, 149500, 37700 | AI28: 0 | AJ28: 2025-03-05 00:00:00 | AK28: 2025-10-13 00:00:00 | AL28: 150800, 269800, 598000 | AM28: 0, 1033875 | AN28: -764075, 150800, 598000 | AO28: 0, 0.5 | AP28: 0.5 | AU28: 0, Winter Round | AV28: OMR | AW28: 0, 2, 4 | AX28: MCQ | AY28: Printing By EI | AZ28: OMR | BB28: CBSE | BC28: Tirupur | BD28: Tamil Nadu | BE28: South | BF28: Tamil Nadu | BG28: National Sales | BH28: 2024-06-01 00:00:00 | BI28: 2025-03-31 00:00:00 | BJ28: Regular School: Active school with student count and rate per student defined | BK28: 22028000023033760, 22028000023124952, 22028000023126540 | BL28: 51788000002754853 | BM28: zcrm_51788000270417181, zcrm_51788000271066068, zcrm_51788000271132113 | BN28: 2024-06-17 00:00:00, 2024-06-24 00:00:00 | BO28: jasper.jessie_ei | BP28: hakim.kanchwala_eiindia1, sourabh.mehta_eiindia | BQ28: jasper.jessie@ei.study | BR28: Jasper jessie | BS28: Vineeth T V | BU28: 2024-07-05 11:51:55, 2024-07-05 11:54:13, 2024-07-05 11:55:14 | BV28: Jerald Arockia | BX28: principalscs@subbiahschools.org | BY28: +914212245252 | BZ28: info@subbiahschools.org | CG28: 0 | CH28: No-1, College Road, | CJ28: 641602 | CK28: No-1, College Road, | CL28: Tirupur | CM28: Tamil Nadu | CN28: 641602 | CP28: No-1, College Road, | CQ28: No-1, College Road,
A29: Retention School | B29: 147 | C29: Nath Valley School | E29: Dropped | F29: 2024 | G29: 2024-07-02 00:00:00 | H29: Ei ASSET | I29: Regular | J29: IN-2022002303 | K29: Approved By Logistic Team | L29: 263400 | M29: 263400 | N29: 263400 | O29: 439 | P29: 600 | Q29: 0 | R29: 0 | T29: 0 | U29: 0 | W29: 0 | X29: Installments | Y29: 3 | AA29: 2024-08-31 00:00:00 | AB29: 89556 | AC29: 2024-09-30 00:00:00 | AD29: 86922 | AE29: 2024-10-31 00:00:00 | AF29: 86922 | AG29: 2000-01-01 00:00:00 | AH29: 0 | AI29: 0 | AJ29: 2024-08-29 00:00:00 | AK29: 2025-01-14 00:00:00 | AL29: 263400 | AM29: 263400 | AN29: 0 | AO29: 0.6 | AP29: 0.6 | AU29: Winter Round | AV29: OMR | AW29: 0 | AX29: MCQ | BB29: CBSE | BC29: Aurangabad | BD29: Maharashtra | BE29: West | BF29: Rest of Maharashtra and Goa | BG29: National Sales | BH29: 2024-07-10 00:00:00 | BI29: 2025-05-31 00:00:00 | BJ29: Regular School: Active school with student count and rate per student defined | BK29: 22028000023275356 | BL29: 51788000002728395 | BM29: zcrm_51788000271349468 | BN29: 2024-07-02 00:00:00 | BO29: aarti.iyer_ei | BP29: hakim.kanchwala_eiindia1 | BQ29: aarti.iyer@ei.study | BR29: Aarti iyer | BS29: Nainesh Bhise | BT29: Aarti Iyer | BU29: 2024-07-05 12:07:22 | BV29: Dr. Sharda Gupta | BW29: Principal | BX29: contact@nathvalleyschool.com | BY29: +919673304848 | BZ29: contact@nathvalleyschool.com | CG29: 0 | CH29: P O Box 567, Cantonment Post Office, Satara Village, Paithan Road | CJ29: 431002 | CK29: P O Box 567, Cantonment Post Office, Satara Village, Paithan Road | CL29: Aurangabad | CM29: Maharashtra | CN29: 431002 | CP29: P O Box 567, Cantonment Post Office, Satara Village, Paithan Road | CQ29: P O Box 567, Cantonment Post Office, Satara Village, Paithan Road
A30: 1-year School | B30: 1482482 | C30: Pathania Public School | D30: =VLOOKUP(B30,'2025'!B:C,2,0) -> Anushka | F30: 2024 | G30: 2024-04-09 00:00:00 | H30: Ei CARES | I30: Regular | J30: IN-2022001887 | K30: Approved By Logistic Team | L30: 540004 | M30: 540004 | N30: 0 | O30: 0 | Q30: 540004 | R30: 750 | S30: 720 | T30: 0 | U30: 0 | W30: 0 | X30: Full Payment | Z30: 2024-03-29 00:00:00 | AA30: 2000-01-01 00:00:00 | AB30: 0 | AC30: 2000-01-01 00:00:00 | AD30: 0 | AE30: 2000-01-01 00:00:00 | AF30: 0 | AG30: 2000-01-01 00:00:00 | AH30: 0 | AI30: 10800 | AJ30: 2024-03-29 00:00:00 | AK30: 2024-03-29 00:00:00 | AL30: 540004 | AM30: 529200 | AN30: 4 | AO30: 0.467 | AP30: 0.41700000000000004 | AQ30: 0.05 | AU30: 0 | AW30: 2 | AX30: MCQ | AY30: Printing By EI | AZ30: OMR | BB30: CBSE | BC30: Rohtak | BD30: Haryana | BE30: North | BF30: Delhi/Haryana | BG30: National Sales | BH30: 2024-04-01 00:00:00 | BI30: 2025-03-31 00:00:00 | BJ30: Regular School: Active school with student count and rate per student defined | BK30: 22028000022000032 | BL30: 51788000002755871 | BM30: zcrm_51788000266942147 | BN30: 2024-04-09 00:00:00 | BO30: vikas.shukla_ei | BP30: fagun.saraiya_eiindia1 | BQ30: vikas.shukla@ei.study | BR30: Vikas shukla | BS30: Anushka Gupta | BU30: 2024-04-10 10:14:10 | BV30: Mr. Anshul Pathania | BX30: patanshul@gmail.com | BY30: +919991599935 | BZ30: ppsrohtak@gmail.com | CA30: Tanvi Pathania | CB30: patanshul@gmail.com | CC30: +919991599935 | CD30: Rajni Gulati | CE30: rajnigulati16091985@gmail.com | CF30: +919416518727 | CG30: 54000 | CH30: 8th K.M. STONE, GOHANA ROAD , ROHTAK | CJ30: 124001 | CK30: 8th K.M. STONE, GOHANA ROAD , ROHTAK | CL30: Rohtak | CM30: Haryana | CN30: 124001 | CO30: RTKP03269A | CP30: Sector 34, Suncity Township-I, Rohtak, Haryana 124001 | CQ30: Sector 34, Suncity Township-I, Rohtak, Haryana 124001
A31: Retention School | B31: 1524162 | C31: SAI International School | D31: =VLOOKUP(B31,'2025'!B:C,2,0) -> Sumit Rana | F31: 2024 | G31: 2024-05-09 00:00:00, 2024-06-05 00:00:00 | H31: Ei ASSET, Ei Mindspark | I31: Regular | J31: IN-2022002034, IN-2022002171 | K31: Approved By Logistic Team | L31: 1578982 | M31: 1683667 | N31: 997400 | O31: 1995 | P31: 500 | Q31: 0 | R31: 0 | T31: 581582 | U31: 600 | V31: 969 | W31: 0 | X31: Full Payment, Installments | Y31: 4 | Z31: 2024-07-01 00:00:00 | AA31: 2000-01-01 00:00:00, 2024-05-11 00:00:00 | AB31: 0, 171567 | AC31: 2000-01-01 00:00:00, 2024-07-05 00:00:00 | AD31: 0, 171567 | AE31: 2000-01-01 00:00:00, 2024-10-05 00:00:00 | AF31: 0, 171567 | AG31: 2000-01-01 00:00:00, 2024-12-31 00:00:00 | AH31: 0, 171567 | AI31: 0, 33938 | AJ31: 2024-10-18 00:00:00, 2024-10-19 00:00:00 | AK31: 2024-10-19 00:00:00, 2025-01-30 00:00:00 | AL31: 686268, 997400 | AM31: 600520, 991757 | AN31: 51810, 5643 | AO31: 0.6667000000000001, 0.6823 | AP31: 0.6667000000000001, 0.6823 | AU31: 0, Summer Round | AV31: OMR | AW31: 0 | AX31: MCQ | BA31: Online | BB31: CBSE | BC31: Bhubaneswar | BD31: Odisha | BE31: East | BF31: Odisha | BG31: National Sales | BH31: 2024-05-10 00:00:00, 2024-06-05 00:00:00 | BI31: 2025-03-31 00:00:00, 2025-04-30 00:00:00 | BJ31: Regular School: Active school with student count and rate per student defined | BK31: 22028000022429064, 22028000022845064 | BL31: 51788000002756667 | BM31: zcrm_51788000269102204, zcrm_51788000270347275 | BN31: 2024-05-09 00:00:00, 2024-06-05 00:00:00 | BO31: lopamudra.das_eiindia1 | BP31: mitul.patel_ei1 | BQ31: lopamudra.das@ei.study | BR31: Lopamudra das | BS31: Lopamudra Das | BU31: 2024-05-09 12:17:02, 2024-06-08 10:02:33 | BV31: Mr. Dipak Somani | BW31: Admin | BX31: dipak@sai.edu.in | BY31: +918598097405 | BZ31: info@saiinternationalschool.com | CA31: Neelkantha Panigrahi | CB31: srprincipal@saiinternational.edu.in | CC31: +918598097404 | CD31: Prakash Sahoo | CE31: principalsecondary@saiinternational.edu.in | CF31: +919910573303 | CG31: 0 | CH31: Plot No 5A, Chandaka Industrial Estate, 1-B Infocity Road,, Bhubaneswar, Odisha | CJ31: 751024 | CK31: Plot No 5A, Chandaka Industrial Estate, 1-B Infocity Road,, Bhubaneswar, Odisha | CL31: Bhubaneswar | CM31: Odisha | CN31: 751024 | CO31: BBNS09089D | CP31: SECUREWAYS LOGISTICS PRIVATE LIMITED (STUDENT GALLERY) Plot No : N / 33 & 34, Chandka Industrial Estate, Near OTV office, Bhubaneswar - 751024, Odisha | CQ31: SAI INTERNATIONAL SCHOOL,PLOT NO-5A, Chandaka I.E, INFOCITY ROAD, PATIA, BHUBANESWAR, Odisha, 751024
